Workbook
Name furnace_part_scale_y: Shop!$C$98
Name dm_furnace_y: Shop!$C$95
Name uptime_hours_yr: 'P-50 Base'!$C$36
Name build_x: Shop!$C$71
Name dm_furnace_y: #REF!
Name part_x: Shop!$C$5
Name build_z: 'P-1'!$C$73
Name printhead_life: 'P-1'!$C$85
Name avail_hours_yr: Shop!$C$34
Name InnoventX: Inputs!$O$104:$O$125
Name s_model: #REF!
Name z_scale: 'P-50 Base'!$C$63
Name xlink_msrp: 'P-1'!$C$119
Name parts_job: Universal!$C$79
Name weeks_yr: 'P-50 Auto'!$C$32
Name furnace_shelves: 'P-1'!$C$112
Name uptime: Universal!$C$38
Name powder_default_price: 'P-50 Base'!$C$43
Name dm_furnace_hw_consumables: Universal!$C$123
Name dm_furnace_x: Universal!$XFD$99
Name furnace_z_spacing: Shop!$C$101
Name furnace_part_scale_z: Universal!$C$129
Name part_only_vol: 'P-50 Base'!$C$8
Name buildbox_msrp: 'P-50 Auto'!$C$118
Name furnace_part_scale_z: 'P-50 Auto'!$C$94
Name furnace_shelves: 'P-50 Auto'!$C$107
Name print_turnaround: 'P-50 Auto'!$C$75
Name sponge_msrp: Shop!$C$46
Name dm_furnace_consumables_material: Shop!$C$105
Name powder_default_price: 'P-1'!$C$43
Name furnace_part_scale_x: 'P-1'!$C$97
Name furnace_utilities_hr: Universal!$C$125
Name floor_rate: 'P-1'!$C$57
Name uptime_hours_yr: 'P-50 Auto'!$C$35
Name part_y: Universal!$C$6
Name xlink_module_msrp: 'P-1'!$C$120
Name printer_msrp: 'P-50 Base'!$C$118
Name total_builds_yr: 'P-1'!$G$12
Name furnace_part_scale_x: Shop!$C$97
Name ShopPlus_4L: Inputs!$F$104:$F$125
Name printer_msrp: Universal!$C$148
Name nitrogen_rate: Universal!$C$61
Name xlink_floorspace: Universal!$C$142
Name ShopPro_4L: Inputs!$I$104:$I$125
Name part_only_vol: Shop!$C$8
Name blender_msrp: 'P-1'!$C$122
Name support_vol: 'P-50 Auto'!$C$9
Name part_scale_y: Universal!$C$76
Name binder_per_yr: 'P-1'!$C$165
Name avail_hours_yr: 'P-50 Base'!$C$34
Name good_parts_job: Shop!$C$28
Name printer_z_base: 'P-50 Base'!$C$89
Name floor_rate: 'P-50 Auto'!$C$56
Name furnace_gas_cons: 'P-50 Base'!$C$114
Name part_z: 'P-50 Auto'!$C$7
Name p_model: 'P-50 Base'!$C$14
Name total_yield: Universal!$C$30
Name y_scale: Universal!$C$72
Name buildbox_msrp: 'P-50 Base'!$C$123
Name weeks_yr: 'P-1'!$C$33

Sheet Change Log
A1: Version | B1: Date | C1: Description
A2: 13.1.0 | B2: 44627 | C2: - changed ExOne printer names to X-Series nomenclature - corrected cells Y34 and Y35 to display correct information - updated MSRP for all systems to match current pricebook
A3: 13.1.1 | B3: 44629 | C3: - corrected cell C68 invalid reference
A4: 13.1.2 | B4: 44652 | C4: - added SiC cost and density data to lookup tables - corrected error where incorrect printer model was shown in cost summary table
A5: 13.1.3 | B5: 44663 | C5: - added S7
A6: 13.1.4 | B6: 44680 | C6: - fixed ShopPro layer speed to match Shop - fixed ShopPro consumables not calculating
A7: 13.2.0 | B7: 44729 | C7: - added ShopPlus 4L, 8L, 12L - added ShopPro 4L, 8L, 12L - updated Al6061 pricing on Production Series from $10-->$30/kg - updated X25Pro layer time to 50s -updated X160Pro layer time to 45s - corrected furnace XY and Z spacing lookups in tab 'Universal', cells C128 and C129 - removed X160Pro Inert - corrected DM Furnace MSRP
A8: 13.2.1 | B8: 44764 | C8: - corrected z-height for ShopPlus 4L and 8L - corrected cell C68 on "Universal" tab to reflect correct value when Furnace set = 1 - removed formula from cell C40 "Universal"
A9: 13.2.2 | B9: 44791 | C9: - added maximum part quantity produced with single unit configuration - C40 - enter this number into C41 to generate single unit configuration cost analysis - updated MSRPs to pricelist - added material specific gas consumption to DM Furnace - added IN625 to Shop material availability
A10: 13.2.3 | B10: 44915 | C10: - fixed P-50 Auto material selection - fixed powder pricing reference in notes - added IN718 for Shop System models
A11: 13.2.4 | B11: 44923 | C11: - added CM Furnace Tube Furnace 1630-20 - added output section without depreciated part cost - removed "Shop_4L" from donut chart title block - added "DM HH Stainless", "440C," "CrMnMoN," and "WC-12Co" to Production Series - verified MSRP hardware pricing to Q4-22 Price List - updated InnoventX DIMMs to match datasheet
A12: 13.2.5 | B12: 44958 | C12: - Corrected InnoventX y-dim from 125 to 160 - adjusted locked cell permissions for override nesting - adjusted locked cell permissions for parts required/ year
A13: 13.2.6 | B13: 45296 | C13: - Modified X-series binder/cleaner/crosslink times based on process team (max Inks) spreadsheet - auto calculate setter raft volume for TurboFuse with X-series - added binder picklist for each printer - updated material availability based on binder selection - updated raw powder pricing based on available market data - Updated DM Furnace to include insulation pack consumable - added PureSinter draft specifications – Updated Elnik furnaces with latest spec data
... A15: 13.2.6 | B15: 45372 | C15: - Updated 3rd party furnace costs

Sheet Inputs
B1: 1 | C1: =B1+1 -> 2 | D1: =C1+1 -> 3 | E1: =D1+1 -> 4 | F1: =E1+1 -> 5 | G1: =F1+1 -> 6 | H1: =G1+1 -> 7 | I1: =H1+1 -> 8 | J1: =I1+1 -> 9 | ... Q1: =P1+1 -> 16
B2: Material
C4: Shop_4L | D4: Shop_8L | E4: Shop_12L | F4: ShopPlus_4L | G4: ShopPlus_8L | H4: ShopPlus_12L | I4: ShopPro_4L | J4: ShopPro_8L | K4: ShopPro_12L | L4: P_1 | M4: P_50_Base | N4: P_50_Auto | O4: InnoventX | P4: X25Pro | Q4: X160Pro
A5: x | B5: Part inputs | S5: =IF(Universal!printer_index<13,"","AquaFuse")
B6: X-scale | C6: 1.167 | D6: 1.167 | E6: 1.167 | F6: 1.167 | G6: 1.167 | H6: 1.167 | I6: 1.167 | J6: 1.167 | K6: 1.167 | L6: =VLOOKUP(Universal!material_sel,Layer_defaults!$A$2:$E$22,3,FALSE) -> 1.16 | M6: =VLOOKUP(Universal!material_sel,Layer_defaults!$A$2:$E$22,3,FALSE) -> 1.16 | N6: =VLOOKUP(Universal!material_sel,Layer_defaults!$A$2:$E$22,3,FALSE) -> 1.16 | O6: 1.18 | P6: 1.18 | Q6: 1.18 | S6: =IF(Universal!printer_index<13,"","CleanFuse")
B7: Y-scale | C7: 1.174 | D7: 1.174 | E7: 1.174 | F7: 1.174 | G7: 1.174 | H7: 1.174 | I7: 1.174 | J7: 1.174 | K7: 1.174 | L7: =VLOOKUP(Universal!material_sel,Layer_defaults!$A$2:$E$22,4,FALSE) -> 1.165 | M7: =VLOOKUP(Universal!material_sel,Layer_defaults!$A$2:$E$22,4,FALSE) -> 1.165 | N7: =VLOOKUP(Universal!material_sel,Layer_defaults!$A$2:$E$22,4,FALSE) -> 1.165 | O7: 1.18 | P7: 1.18 | Q7: 1.18 | S7: =IF(Universal!printer_index<13,"","FluidFuse")
B8: Z-scale | C8: 1.21 | D8: 1.21 | E8: 1.21 | F8: 1.21 | G8: 1.21 | H8: 1.21 | I8: 1.21 | J8: 1.21 | K8: 1.21 | L8: =VLOOKUP(Universal!material_sel,Layer_defaults!$A$2:$E$22,5,FALSE) -> 1.18 | M8: =VLOOKUP(Universal!material_sel,Layer_defaults!$A$2:$E$22,5,FALSE) -> 1.18 | N8: =VLOOKUP(Universal!material_sel,Layer_defaults!$A$2:$E$22,5,FALSE) -> 1.18 | O8: 1.18 | P8: 1.18 | Q8: 1.18 | S8: =IF(Universal!printer_index<13,"","PhenolFuse")
A9: x | B9: Printer inputs | S9: =IF(Universal!printer_index<13,"","TurboFuse")
B10: Layer speed | C10: 26 | D10: 26 | E10: 26 | F10: 26 | G10: 26 | H10: 26 | I10: 26 | J10: 26 | K10: 26 | L10: 2.63 | M10: 2.98 | N10: 2.98 | O10: 22.23 | P10: 46 | Q10: 46 | R10: sec | S10: =IF(Universal!printer_index<10,"SS01","") -> SS01
B11: X-Series Layer speed with TurboFuse | F11: 26 | G11: 26 | H11: 26 | I11: 26 | J11: 26 | K11: 26 | L11: 2.63 | M11: 2.98 | N11: 2.98 | O11: 22.23 | P11: 24 | Q11: 46 | S11: =IF(Universal!printer_index<10,"",IF(Universal!printer_index>12,"","SPJ04"))
B12: Build box X-dim | C12: 350 | D12: 350 | E12: 350 | F12: 350 | G12: 350 | H12: 350 | I12: 350 | J12: 350 | K12: 350 | L12: 200 | M12: 490 | N12: 490 | O12: 75 | P12: 270 | Q12: 500 | R12: mm
B13: Build box Y-dim | C13: 220 | D13: 220 | E13: 220 | F13: 220 | G13: 220 | H13: 220 | I13: 220 | J13: 220 | K13: 220 | L13: 100 | M13: 380 | N13: 380 | O13: 170 | P13: 420 | Q13: 800 | R13: mm
B14: Build box Z-dim | C14: 50 | D14: 100 | E14: 150 | F14: 50 | G14: 100 | H14: 150 | I14: 50 | J14: 50 | K14: 150 | L14: 40 | M14: 260 | N14: 260 | O14: 75 | P14: 270 | Q14: 400 | R14: mm
B15: Bed density | C15: 0.56 | D15: 0.56 | E15: 0.56 | F15: 0.56 | G15: 0.56 | H15: 0.56 | I15: 0.56 | J15: 0.56 | K15: 0.56 | L15: 0.6 | M15: 0.6 | N15: 0.6 | O15: 0.59 | P15: 0.59 | Q15: 0.59
B16: Powder + overflow ratio | C16: 1.8 | D16: 1.8 | E16: 1.8 | F16: 1.8 | G16: 1.8 | H16: 1.8 | I16: 1.8 | J16: 1.8 | K16: 1.8 | L16: 6 | M16: 6 | N16: 6 | O16: 4 | P16: 4 | Q16: 4
B17: Powder loss percentage | C17: 0.005 | D17: 0.005 | E17: 0.005 | F17: 0.005 | G17: 0.005 | H17: 0.005 | I17: 0.005 | J17: 0.005 | K17: 0.005 | L17: 0.005 | M17: 0.001 | N17: 0.001 | O17: 0.001 | P17: 0.001 | Q17: 0.001
B18: Binder void ratio | C18: 0.68181818 | D18: 0.68181818 | E18: 0.68181818 | F18: 0.68181818 | G18: 0.68181818 | H18: 0.68181818 | I18: 0.68181818 | J18: 0.68181818 | K18: 0.68181818 | L18: 0.8 | M18: 0.7 | N18: 0.7 | O18: 0.8 | P18: 0.8 | Q18: 0.8
B19: Purge frequency | C19: 16 | D19: 16 | E19: 16 | F19: 16 | G19: 16 | H19: 16 | I19: 16 | J19: 16 | K19: 16 | L19: 50 | M19: 100 | N19: 100 | O19: 2 | P19: 2 | Q19: 2 | R19: layers
B20: Binder purge volume | C20: 1.5 | D20: 1.5 | E20: 1.5 | F20: 1.5 | G20: 1.5 | H20: 1.5 | I20: 1.5 | J20: 1.5 | K20: 1.5 | L20: 5 | M20: 20 | N20: 20 | O20: 1.25 | P20: 1.5 | Q20: 10 | R20: mL
B21: Binder purge btwn parts | C21: Yes | D21: Yes | E21: Yes | F21: Yes | G21: Yes | H21: Yes | I21: Yes | J21: Yes | K21: Yes | L21: Yes | M21: Yes | N21: Yes | O21: No | P21: No | Q21: No
B22: Printer XY border | C22: 4 | D22: 4 | E22: 4 | F22: 4 | G22: 4 | H22: 4 | I22: 4 | J22: 4 | K22: 4 | L22: 8.5 | M22: 20 | N22: 20 | O22: 5 | P22: 10 | Q22: 10 | R22: mm
B23: Printer Z base plate | C23: 3 | D23: 3 | E23: 3 | F23: 3 | G23: 3 | H23: 3 | I23: 3 | J23: 3 | K23: 3 | L23: 4 | M23: 10 | N23: 10 | O23: 1 | P23: 4 | Q23: 1 | R23: mm
B24: Printer XY spacing | C24: 1 | D24: 1 | E24: 1 | F24: 1 | G24: 1 | H24: 1 | I24: 1 | J24: 1 | K24: 1 | L24: 1 | M24: 1 | N24: 1 | O24: 1 | P24: 5 | Q24: 1 | R24: mm
B25: Printer Z spacing | C25: 1 | D25: 1 | E25: 1 | F25: 1 | G25: 1 | H25: 1 | I25: 1 | J25: 1 | K25: 1 | L25: 0.4 | M25: 0.4 | N25: 0.4 | O25: 0.5 | P25: 5 | Q25: 0.5 | R25: mm
A26: x | B26: Printer layer thickness
B27: Min layer thickness | C27: 50 | D27: 50 | E27: 50 | F27: 50 | G27: 50 | H27: 50 | I27: 50 | J27: 50 | K27: 50 | L27: 35 | M27: 35 | N27: 35 | O27: 30 | P27: 30 | Q27: 30 | R27: um
B28: Max layer thickness | C28: 100 | D28: 100 | E28: 100 | F28: 100 | G28: 100 | H28: 100 | I28: 100 | J28: 100 | K28: 100 | L28: 150 | M28: 150 | N28: 150 | O28: 200 | P28: 200 | Q28: 200 | R28: um
B29: Increment | C29: 25 | D29: 25 | E29: 25 | F29: 25 | G29: 25 | H29: 25 | I29: 25 | J29: 25 | K29: 25 | L29: 5 | M29: 5 | N29: 5 | O29: 5 | P29: 5 | Q29: 5 | R29: um
B30: Default | C30: 75 | D30: 75 | E30: 75 | F30: 75 | G30: 75 | H30: 75 | I30: 75 | J30: 75 | K30: 75 | L30: 65 | M30: 65 | N30: 65 | O30: 50 | P30: 50 | Q30: 50 | R30: um
A31: x | B31: Auxiliary equipment inputs
B32: Crosslink time | C32: =IF(OR(Shop!s_model="4L",Shop!s_model="8L"),20,26) -> 26 | D32: =IF(OR(Shop!s_model="4L",Shop!s_model="8L"),20,26) -> 26 | E32: =IF(OR(Shop!s_model="4L",Shop!s_model="8L"),20,26) -> 26 | F32: =IF(OR(Shop!s_model="4L",Shop!s_model="8L"),20,26) -> 26 | G32: =IF(OR(Shop!s_model="4L",Shop!s_model="8L"),20,26) -> 26 | H32: =IF(OR(Shop!s_model="4L",Shop!s_model="8L"),20,26) -> 26 | I32: 20 | J32: 20 | K32: 20 | L32: 4.5 | M32: 40 | N32: 40 | O32: =12+(((Universal!build_height-25.4)/25.4)*4) -> 25.937008 | P32: =12+(((Universal!build_height-25.4)/25.4)*4) -> 25.937008 | Q32: =12+(((Universal!build_height-25.4)/25.4)*4) -> 25.937008 | R32: hrs | S32: SPJ = (build height / 30 * 6) + (build height / 30 * 2) + 10 + 10 = hours
B33: X-Series Crosslink time with TurboFuse | L33: 4.5 | M33: 40 | N33: 40 | O33: =(Universal!build_height/30*6)+(Universal!build_height/30*2)+10+10 -> 50.373333 | P33: =(Universal!build_height/30*6)+(Universal!build_height/30*2)+10+10 -> 50.373333 | Q33: =(Universal!build_height/30*6)+(Universal!build_height/30*2)+10+10 -> 50.373333
B34: Printer builds / oven run | C34: 2 | D34: 2 | E34: 2 | F34: 2 | G34: 2 | H34: 2 | I34: 2 | J34: 2 | K34: 2 | L34: 6 | M34: 2 | N34: 2 | O34: 4 | P34: =IF(Universal!$C$14="TurboFuse",1,2) -> 2 | Q34: 1 | S34: all X-series Metal Fuse = 12+(((build height - 25.4)/25.4)*4)
B35: Powder blender capacity | C35: 45 | D35: 45 | E35: 45 | F35: 45 | G35: 45 | H35: 45 | I35: 45 | J35: 45 | K35: 45 | L35: 45 | M35: 0 | N35: 0 | O35: 45 | P35: 500 | Q35: 0 | R35: kg
B36: Printers / PPU auto | C36: 0 | D36: 0 | E36: 0 | F36: 0 | G36: 0 | H36: 0 | I36: 0 | J36: 0 | K36: 0 | L36: 0 | M36: 1 | N36: 1 | O36: 0 | P36: 0 | Q36: 2
B37: Depowders / PPU auto | C37: 0 | D37: 0 | E37: 0 | F37: 0 | G37: 0 | H37: 0 | I37: 0 | J37: 0 | K37: 0 | L37: 0 | M37: 2 | N37: 2 | O37: 0 | P37: 0 | Q37: 2
A38: x | B38: Consumables inputs
B39: Printhead life | C39: 4000 | D39: 4000 | E39: 4000 | F39: 4000 | G39: 4000 | H39: 4000 | I39: 4000 | J39: 4000 | K39: 4000 | L39: 2500 | M39: 2500 | N39: 2500 | O39: 2500 | P39: 2500 | Q39: 2500 | R39: layers / L
B40: Wiper cartridge life | C40: 8000 | D40: 8000 | E40: 8000 | F40: 8000 | G40: 8000 | H40: 8000 | I40: 8000 | J40: 8000 | K40: 8000 | L40: 0 | M40: 0 | N40: 0 | O40: 120000 | P40: 0 | Q40: 0 | R40: layers
B41: Binder sponge life | C41: 10 | D41: 10 | E41: 10 | F41: 10 | G41: 10 | H41: 10 | I41: 10 | J41: 10 | K41: 10 | L41: 0 | M41: 0 | N41: 0 | O41: 80000 | P41: 0 | Q41: 0 | R41: L
...

Sheet Universal
A2: x | B2: =MID(CELL("filename",A1),SEARCH("[",CELL("filename",A1))+1,LEN(CELL("filename",A1))-SEARCH("[",CELL("filename",A1))-15) -> #VALUE! | F2: =IF(Universal!printer_index<10,"SHOP SYSTEM",IF(Universal!printer_index<13,"PRODUCTION SYSTEM","X-SERIES")) -> SHOP SYSTEM | K2: Privileged & DM Confidential | M2: x | N2: =Universal!printer_sel&" part cost outputs with depreciation" -> Shop_12L part cost outputs with depreciation | AD2: x | AE2: =Universal!printer_sel&" part cost outputs without depreciation" -> Shop_12L part cost outputs without depreciation
N3: Printer & aux MSRP | P3: =G20+G35+G47+K34 -> 345955 | R3: ="Printed parts / build" -> Printed parts / build | T3: =Universal!parts_job -> 135 | AE3: Printer & aux MSRP | AG3: =G20+G35+G47+K34 -> 345955 | AI3: ="Printed parts / build" -> Printed parts / build | AK3: =Universal!parts_job -> 135
A4: x | B4: Part inputs (pre-scaling) | E4: x | F4: Printer usage calculation | I4: x | J4: Furnace part cost calculation | N4: Furnace MSRP | P4: =K17 -> 210000 | R4: Part nesting density | T4: =G17 -> 0.51568461 | AE4: Furnace MSRP | AG4: =K17 -> 210000 | AI4: Part nesting density | AK4: =G17 -> 0.51568461
B5: X-dim (incl. supports) | C5: 30 | D5: mm | F5: Powder volume / part | G5: =Universal!part_vol_scale*Universal!bed_density -> 18760.866 | H5: mm3 | J5: Furnace selection | K5: =Universal!furnace_sel -> DM PureSinter | N5: Total equipment MSRP | P5: =SUM(P3:P4) -> 555955 | AE5: Total equipment MSRP | AG5: =SUM(AG3:AG4) -> 555955
B6: Y-dim (incl. supports) | C6: 30 | D6: mm | F6: Powder mass / part | G6: =G5*Universal!density_selected*10^3 -> 145.2091 | H6: g | J6: Furnace X-dim | K6: =Universal!furnace_x_dim -> 244 | L6: mm | N6: =Universal!printer_sel&" printers req." -> Shop_12L printers req. | P6: =G11 -> 1 | R6: Printer builds / week | T6: =T8/Universal!weeks_yr -> 3.2921811 | AE6: =Universal!printer_sel&" printers req." -> Shop_12L printers req. | AG6: =G11 -> 1 | AI6: Printer builds / week | AK6: =AK8/Universal!weeks_yr -> 3.2921811
B7: Z-dim (incl. supports) | C7: 30 | D7: mm | F7: Powder mass / build | G7: =(G6*Universal!parts_job)/10^3+((Universal!build_vol*Universal!bed_density*Universal!density_selected*Universal!powder_ratio)-(G6*Universal!parts_job)/1000)*Universal!powder_loss_percentage -> 19.847338 | H7: kg | J7: Furnace Y-dim | K7: =Universal!furnace_y_dim -> 270 | L7: mm | N7: Furnaces req. | P7: =K15 -> 1 | R7: Printer builds / month | T7: =T6*4 -> 13.168724 | AE7: Furnaces req. | AG7: =K15 -> 1 | AI7: Printer builds / month | AK7: =T6*4 -> 13.168724
B8: Part volume | C8: 20208.8 | D8: mm3 | F8: Binder volume / part | G8: =Universal!part_vol_scale*(1-Universal!bed_density)*Universal!binder_void_ratio -> 10050.464 | H8: mm3 | J8: Furnace Z-dim | K8: =Universal!furnace_z_dim -> 265 | L8: mm | R8: Printer builds / year | T8: =Universal!total_builds_yr -> 164.60905 | AI8: Printer builds / year | AK8: =Universal!total_builds_yr -> 164.60905
B9: Support volume | C9: =IF(Universal!printer_index<13,"0",IF(C14="TurboFuse",(Universal!part_scale_x*Universal!part_scale_y),"0")) -> 0 | D9: mm3 | F9: Binder volume / build | G9: =IF(Universal!printer_index<12,((Universal!parts_job*G8)/10^6)+((Universal!binder_purge_vol*(Universal!build_layers/Universal!binder_purge_freq))/10^3),(G8*Universal!parts_job/10^6+(Universal!build_layers/Universal!binder_purge_freq+2)*Universal!binder_purge_vol/10^3-IF(VLOOKUP(Inputs!$B$20,Inputs!$B:$Q,Universal!printer_index+1,0)="No",((C20-1)*Universal!printer_z_spacing+Universal!printer_z_base)/Universal!layer_thickness_sel/Universal!binder_purge_freq*Universal!binder_purge_vol/10^3,0))) -> 1.4992189 | H9: L | J9: Furnace parts / run | K9: =IF(Universal!furnace_sel="Continuous",Universal!part_req,ROUNDDOWN((Universal!furnace_x_dim+Universal!furnace_xy_spacing)/(Universal!furnace_part_scale_x+Universal!furnace_xy_spacing),0)*ROUNDDOWN((Universal!furnace_y_dim+Universal!furnace_xy_spacing)/(Universal!furnace_part_scale_y+Universal!furnace_xy_spacing),0)*MIN(Universal!furnace_shelves,ROUNDDOWN(Universal!furnace_z_dim/(Universal!furnace_part_scale_z+Universal!furnace_rack_thickness+Universal!furnace_z_spacing),0))) -> 216 | N9: Operating (i.e. "running") part costs
B10: Part + support volume | C10: =Universal!part_only_vol+Universal!support_vol -> 20208.8 | D10: mm3 | F10: Cleaner volume / build | G10: =IF(Universal!printer_index<13,"",(Universal!build_layers/Universal!cleaner_freq)*Universal!cleaner_cycle_vol/10^3) | H10: L | J10: Furnace loading parts / hour | K10: =C58 -> 500 | N10: Printed part cost | P10: =P32+P33+P35+P36 -> 14.641018 | R10: =IF($C$15="Yes","Sintered","Green")&" parts / week" -> Sintered parts / week | T10: =T12/Universal!weeks_yr -> 400 | AI10: =IF($C$15="Yes","Sintered","Green")&" parts / week" -> Sintered parts / week | AK10: =T12/Universal!weeks_yr -> 400
F11: Printers required (rounded) | G11: =ROUNDUP(Universal!part_req/Universal!part_capacity,0) -> 1 | J11: Run time + turnaround | K11: =Universal!furnace_time_cycle+K9/K10*2 -> 23.864 | L11: hrs | N11: =IF(C15="Yes","Sintered","Green")&" part cost" -> Sintered part cost | P11: =T38-T34-T37 -> 17.324828 | R11: =IF($C$15="Yes","Sintered","Green")&" parts / month" -> Sintered parts / month | T11: =T10*4 -> 1600 | AE11: Operating (i.e. "running") part costs | AI11: =IF($C$15="Yes","Sintered","Green")&" parts / month" -> Sintered parts / month | AK11: =T10*4 -> 1600
A12: x | B12: Build inputs & process capacity | F12: Printer utilization | G12: =Universal!part_req/Universal!good_parts_job*Universal!print_time_trn -> 1888.1573 | H12: hrs | J12: Time per printer build | K12: =IFERROR(Universal!good_parts_job/K9*K11,"N.A.") -> 13.4235 | L12: hrs | N12: =N10&" / cc" -> Printed part cost / cc | P12: =P10/Universal!part_only_vol*10^3 -> 0.72448724 | R12: =IF($C$15="Yes","Sintered","Green")&" parts / year" -> Sintered parts / year | T12: =Universal!part_req -> 20000 | AE12: Printed part cost | AG12: =P32+P33+P35+P36 -> 14.641018 | AI12: =IF($C$15="Yes","Sintered","Green")&" parts / year" -> Sintered parts / year | AK12: =Universal!part_req -> 20000
B13: Printer model | C13: Shop_12L | F13: Builds / year | G13: =Universal!part_req/Universal!good_parts_job -> 164.60905 | J13: Build capacity / year | K13: =IF(Universal!furnace_sel="Continuous",(240000/2.2)/(Universal!good_parts_job*Universal!part_vol*Universal!density_selected),ROUNDDOWN(Universal!total_hours_yr/K12,0)) -> 625 | N13: =N11&" / cc" -> Sintered part cost / cc | P13: =P11/Universal!part_only_vol*10^3 -> 0.85729126 | AE13: =IF(C15="Yes","Sintered","Green")&" part cost" -> Sintered part cost | AG13: =T38-T34-T37 -> 17.324828
B14: Binder Used | F14: Builds / month | G14: =G13/12 -> 13.717421 | J14: Runs / year | K14: =IFERROR(ROUNDUP(Universal!part_req/K9,0),"N.A.") -> 93 | R14: ="Printer util (QTY: "&G11&")" -> Printer util (QTY: 1) | T14: =G15 -> 0.33717095 | AE14: =AE12&" / cc" -> Printed part cost / cc | AG14: =AG12/Universal!part_only_vol*10^3 -> 0.72448724 | AI14: ="Printer util (QTY: "&X11&")" -> Printer util (QTY: ) | AK14: =G15 -> 0.33717095
B15: Include sintering? | C15: Yes | F15: Printer utilization (% of available) | G15: =G12/(Universal!avail_hours_yr*Universal!printers_req) -> 0.33717095 | J15: Furnaces required (rounded) | K15: =IFERROR(ROUNDUP(Universal!total_builds_yr/K13,0),"N.A.") -> 1 | N15: Burdened (i.e. "depreciated") part costs | R15: ="Oven util (QTY: "&G33&")" -> Oven util (QTY: 1) | T15: =G34/(G33*Universal!total_hours_yr) -> 0.19834085 | AE15: =AE13&" / cc" -> Sintered part cost / cc | AG15: =AG13/Universal!part_only_vol*10^3 -> 0.85729126 | AI15: ="Oven util (QTY: "&X33&")" -> Oven util (QTY: ) | AK15: =G34/(G33*Universal!total_hours_yr) -> 0.19834085
B16: Furnace selection | C16: DM PureSinter | D16: =IF(OR(Universal!furnace_sel="DM",Universal!furnace_sel="Continuous"),,"ft3") -> ft3 | F16: Printer utilization (% 24x7) | G16: =G12/(Universal!total_hours_yr*Universal!printers_req) -> 0.22478063 | J16: Furnace utilization | K16: =IFERROR(K11*K14,"N.A.") -> 2219.352 | L16: hrs | N16: Printed part cost | P16: =SUM(P32:P36) -> 15.293515 | R16: ="Depowder util (QTY: "&G45&")" -> Depowder util (QTY: 1) | T16: =G46/(G45*Universal!uptime_hours_yr) -> 0.1010435 | AI16: ="Depowder util (QTY: "&X45&")" -> Depowder util (QTY: ) | AK16: =G46/(G45*Universal!uptime_hours_yr) -> 0.1010435
B17: Debind + Sinter | C17: Integrated | F17: Build box nesting density | G17: =Universal!part_vol_scale*Universal!parts_job/Universal!build_vol -> 0.51568461 | J17: Furnace investment | K17: =IF(C15="No",0,Universal!furnace_msrp*K15) -> 210000 | N17: =IF(C15="Yes","Sintered","Green")&" part cost" -> Sintered part cost | P17: =T46 -> 18.464743 | R17: ="Furnace util (QTY: "&IF(Universal!furnace_sel="DM",K15,K15)&")" -> Furnace util (QTY: 1) | T17: =K16/(Universal!total_hours_yr*K15) -> 0.26420857 | AI17: ="Furnace util (QTY: "&IF(Universal!furnace_sel="DM",AB15,AB15)&")" -> Furnace util (QTY: ) | AK17: =K16/(Universal!total_hours_yr*K15) -> 0.26420857
B18: Limit furnace to QTY 1 | C18: No | J18: ="Annual depreciation (@ "&Universal!furnace_depr&" yrs)" -> Annual depreciation (@ 7 yrs) | K18: =K17/Universal!furnace_depr+Universal!floor_rate*K15*Universal!furnace_floorspace -> 30152 | N18: Printed part cost / cc | P18: =P16/Universal!part_only_vol*10^3 -> 0.756775
B19: Calculated nested parts / job | C19: =ROUNDDOWN((Universal!build_x-Universal!printer_xy_border*2+Universal!printer_xy_spacing)/(Universal!part_scale_x+Universal!printer_xy_spacing),0)*ROUNDDOWN((Universal!build_y-Universal!printer_xy_border*2+Universal!printer_xy_spacing)/(Universal!part_scale_y+Universal!printer_xy_spacing),0)*ROUNDDOWN((Universal!build_z-Universal!printer_z_base+Universal!printer_z_spacing)/(Universal!part_scale_z+Universal!printer_z_spacing),0) -> 135 | E19: x | F19: Printer part cost calculation | J19: Depreciation / part | K19: =K18*K16/(Universal!total_hours_yr*K15)/Universal!part_req -> 0.39832084 | N19: =IF(C15="Yes","Sintered","Green")&" part cost / cc" -> Sintered part cost / cc | P19: =P17/Universal!part_only_vol*10^3 -> 0.91369814 | R19: Labor hrs / year | T19: =Universal!total_builds_yr*(Universal!print_trnaround+Universal!xlink_trnaround+G43+IF(Universal!ppu_auto_on,Universal!ppu_auto_trnaround,K26/K27*Universal!powder_trnaround))+K14*K9/K10*2 -> 742.06013 | AI19: Labor hrs / year | AK19: =Universal!total_builds_yr*(Universal!print_trnaround+Universal!xlink_trnaround+G43+IF(Universal!ppu_auto_on,Universal!ppu_auto_trnaround,K26/K27*Universal!powder_trnaround))+K14*K9/K10*2 -> 742.06013
B20: Calculated build height | C20: =Universal!printer_z_base+(Universal!part_scale_z)*ROUNDDOWN((Universal!build_z-Universal!printer_z_base+Universal!printer_z_spacing)/(Universal!part_scale_z+Universal!printer_z_spacing),0)+Universal!printer_z_spacing*(ROUNDDOWN((Universal!build_z-Universal!printer_z_base+Universal!printer_z_spacing)/(Universal!part_scale_z+Universal!printer_z_spacing),0)-1) -> 113.9 | D20: mm | F20: Printer investment (incl. build box) | G20: =(Universal!printer_msrp+kegs_msrp)*Universal!printers_req+Universal!buildbox_msrp*build_box_qty+Universal!transfer_cart_msrp -> 268780 | J20: Consumables / part | K20: =Universal!furnace_consumables_run/K9 -> 0.27777778 | N20: Notes & assumptions: | AE20: Notes & assumptions:
B21: Calculated part layers | C21: =ROUNDDOWN((Universal!build_z-Universal!printer_z_base+Universal!printer_z_spacing)/(Universal!part_scale_z+Universal!printer_z_spacing),0) -> 3 | F21: ="Annual depreciation (@ "&Universal!dm_depr&" yrs)" -> Annual depreciation (@ 7 yrs) | G21: =G20/Universal!dm_depr+Universal!floor_rate*Universal!printers_req*Universal!printer_floorspace -> 38704.215 | J21: Labor $ / part | K21: =IF(C15="No",0,Universal!labor_rate*(K9/K10*2)/K9) -> 0.08 | N21: 1. Pricing is not final unless on an official DM quote and is subject to change. Does not include installation, training, shipping, or taxes. | AE21: 1. Pricing is not final unless on an official DM quote and is subject to change. Does not include installation, training, shipping, or taxes.
B22: Override nesting | C22: No | F22: Powder $ / part | G22: =IF(C46<>"",C46,Universal!powder_price)*G7/Universal!good_parts_job -> 8.167629 | J22: Utilities / part | K22: =IF(Universal!furnace_sel="Continuous",Universal!furnace_utilities_hr*Universal!total_hours_yr/Universal!part_req,IF(Universal!furnace_sel="DM",(Universal!furnace_power_cons*Universal!power_rate*Universal!furnace_time_cycle+Universal!forming_gas_rate*Universal!furnace_gas_cons)/K9,(Universal!argon_rate*Universal!furnace_gas_cons+Universal!power_rate*Universal!furnace_power_cons)*Universal!furnace_time_cycle/K9)) -> 1.7590741 | N22: ="2. DM Equipment MSRP includes printer build boxes ("&MAX(2*G11,G33*G30+ROUNDUP(G31/Universal!print_time_trn,0))&"x), powder kegs, and transfer cart." -> 2. DM Equipment MSRP includes printer build boxes (4x), powder kegs, and transfer cart. | AE22: ="2. DM Equipment MSRP includes printer build boxes ("&MAX(2*X11,X33*X30+ROUNDUP(X31/Universal!print_time_trn,0))&"x), powder kegs, and transfer cart." -> 2. DM Equipment MSRP includes printer build boxes (0x), powder kegs, and transfer cart.
B23: Override parts / job | C23: 2578 | F23: Binder $ / part | G23: =Universal!binder_price*G9/Universal!good_parts_job -> 3.701775 | N23: 3. Consumables includes printer items (e.g. printheads, wiper cartridges, etc.) and, if applicable, Desktop Metal Furnace items (e.g. setter plates, shelving, oil, liners, etc.). | AE23: 3. Consumables includes printer items (e.g. printheads, wiper cartridges, etc.) and, if applicable, Desktop Metal Furnace items (e.g. setter plates, shelving, oil, liners, etc.).
B24: Override build height | C24: 125 | D24: mm | F24: Depreciation $ / part | G24: =G21*G12/(Universal!avail_hours_yr*Universal!printers_req)/Universal!part_req -> 0.65249684 | I24: x | J24: Powder processing part cost calculation | N24: 4. Includes utilities costs for gas (as required), electricity, and floorspace. | AE24: ="5. "&T43&" powder at "&TEXT(IF($C$46="",Universal!powder_price,$C$46),"$0.00")&"/kg and binder at "&TEXT(Universal!binder_price,"$0.00")&"/L. Volume pricing may be available." -> 5. 0.480075345595028 powder at $50.00/kg and binder at $300.00/L. Volume pricing may be available.
B25: Override part layers | C25: 8 | F25: Consumables $ / part | G25: =IF(Universal!printer_index<14,Universal!printhead_msrp*Universal!build_layers/Universal!printhead_life+Universal!wiper_msrp*Universal!build_layers/Universal!wiper_life+Universal!sponge_msrp*G9/Universal!sponge_life,Universal!printhead_msrp*G9/Universal!printhead_life+IF(Universal!printer_index>=14,Universal!cleaner_msrp*G10))/Universal!good_parts_job -> 2.6331773 | J25: PPU auto? | K25: =IF(C104<>0,TRUE,FALSE) -> FALSE | N25: ="5. "&C45&" powder at "&TEXT(IF($C$46="",Universal!powder_price,$C$46),"$0.00")&"/kg and "&C14&" binder at "&TEXT(Universal!binder_price,"$0.00")&"/L. Volume pricing may be available." -> 5. 17-4PH powder at $50.00/kg and binder at $300.00/L. Volume pricing may be available. | AE25: ="6. Key process assumptions: (i) "&T24*1000&" micron printed layer height; (ii) $"&Universal!labor_rate&"/hr labor rate; (iii) Printer, depowdering, and powder handling equipment @ "&T32&" x "&T33&" x "&Universal!weeks_yr&" x "&Universal!uptime*100&"% uptime" -> 6. Key process assumptions: (i) 0 micron printed layer height; (ii) $20/hr labor rate; (iii) Printer, depowdering, and powder handling equipment @ 11.8694039397328 x 2.91095512588277 x 50 x 80% uptime
B26: Layer thickness | C26: 0.075 | D26: mm | F26: Labor $ / part | G26: =Universal!print_trnaround*Universal!labor_rate/Universal!good_parts_job -> 0.082304527 | J26: Loose powder / build | K26: =(Universal!build_vol*Universal!bed_density*Universal!powder_ratio*Universal!density_selected-G7) -> 48.577841 | L26: kg | N26: ="6. Key process assumptions: (i) "&C26*1000&" micron printed layer height; (ii) $"&Universal!labor_rate&"/hr labor rate; (iii) Printer, depowdering, and powder handling equipment @ "&C34&" x "&C35&" x "&Universal!weeks_yr&" x "&Universal!uptime*100&"% uptime" -> 6. Key process assumptions: (i) 75 micron printed layer height; (ii) $20/hr labor rate; (iii) Printer, depowdering, and powder handling equipment @ 16 x 7 x 50 x 80% uptime | AF26: =" (iv) "&X41&" parts/hr depowdering rate; (v) "&Universal!total_yield*100&"% overall process yield; (vi) "&Universal!dm_depr&"yr DM equipment depreciation;" -> (iv) parts/hr depowdering rate; (v) 90% overall process yield; (vi) 7yr DM equipment depreciation;
B27: Layer thickness default | C27: =VLOOKUP("Default",$B$217:$C$251,2,0) -> 0.075 | D27: mm | F27: Utilities $ / part | G27: =(Universal!power_rate*Universal!printer_pwr*(Universal!print_time_trn-Universal!print_trnaround))*Universal!printers_req/Universal!good_parts_job+(Universal!floor_rate*Universal!printer_floorspace*Universal!printers_req/Universal!part_capacity) -> 0.056131891 | J27: Powder blender capacity | K27: =IF(NOT(Universal!ppu_auto_on),C103,"N.A.") -> 45 | L27: kg | O27: =" (iv) "&G42&" parts/hr depowdering rate; (v) "&Universal!total_yield*100&"% overall process yield; (vi) "&Universal!dm_depr&"yr DM equipment depreciation;" -> (iv) 60 parts/hr depowdering rate; (v) 90% overall process yield; (vi) 7yr DM equipment depreciation; | AF27: =" (vii) Drying oven "&IF(T13="Yes","& sintering ",)&"equipment @ 24 x 7 x "&Universal!weeks_yr&" x "&Universal!uptime*100&"% uptime; (viii) "&IF(T13="Yes",Universal!furnace_depr&"yr MIM furnace depreciation; (iv) ",)&Universal!total_yield*100&"% overall process yield" -> (vii) Drying oven equipment @ 24 x 7 x 50 x 80% uptime; (viii) 90% overall process yield
B28: Printed layers | C28: =ROUNDUP(Universal!build_height/Universal!layer_thickness_sel,0) -> 1519 | J28: ="Blend time + "&Universal!powder_trnaround&"hrs turnaround" -> Blend time + 0.25hrs turnaround | K28: =IF(NOT(Universal!ppu_auto_on),Universal!print_time_trn+Universal!powder_trnaround,"N.A.") -> 11.720556 | L28: hrs | O28: =" (vii) Drying oven "&IF(C15="Yes","& sintering ",)&"equipment @ 24 x 7 x "&Universal!weeks_yr&" x "&Universal!uptime*100&"% uptime; (viii) "&IF(C15="Yes",Universal!furnace_depr&"yr MIM furnace depreciation; (iv) ",)&Universal!total_yield*100&"% overall process yield" -> (vii) Drying oven & sintering equipment @ 24 x 7 x 50 x 80% uptime; (viii) 7yr MIM furnace depreciation; (iv) 90% overall process yield
B29: ="Print time + "&Universal!print_trnaround&"hrs turnaround" -> Print time + 0.5hrs turnaround | C29: =C28*Universal!layer_speed/(60*60)+Universal!print_trnaround -> 11.470556 | D29: hrs | E29: x | F29: Drying oven part cost calculation | J29: Powder capacity / year | K29: =IF(NOT(Universal!ppu_auto_on),K27*Universal!uptime_hours_yr/K28,"N.A.") -> 17200.55 | L29: kg
B30: Overall process yield | C30: 0.9 | F30: Printer builds / oven run | G30: =VLOOKUP($F$30,Inputs!$B:$Q,Universal!printer_index+1,0) -> 2 | J30: Blenders required (rounded) | K30: =IF(NOT(Universal!ppu_auto_on),ROUNDUP(Universal!total_builds_yr*K26/K29,0),"N.A.") -> 1
B31: Good parts / job | C31: =IF(Universal!override_nesting="Yes",IF(C23=0,C19,C23),C19)*C30 -> 121.5 | F31: ="Dry time + "&Universal!xlink_trnaround&"hrs turnaround" -> Dry time + 0.5hrs turnaround | G31: =C101*Universal!build_height/Universal!build_z+Universal!xlink_trnaround -> 20.242667 | H31: hrs | J31: Powder blender utilization (hrs) | K31: =IF(NOT(Universal!ppu_auto_on),Universal!total_builds_yr*K26/K27*K28,"N.A.") -> 2082.7043 | L31: hrs | N31: =Universal!printer_sel&" "&LOWER(N11)&" allocation" -> Shop_12L sintered part cost allocation | V31: Cost model template output | AE31: =Universal!printer_sel&" "&LOWER(AE13)&" allocation" -> Shop_12L sintered part cost allocation | AM31: Cost model template output
A32: x | F32: Build capacity / year | G32: =ROUNDDOWN(G30*Universal!total_hours_yr/G31,0) -> 829 | J32: PPU autos required (rounded) | K32: =IFERROR(MAX(ROUNDUP(G11/C104,0),ROUNDUP(G45/C105,0)),"N.A. ") -> N.A. | N32: Printer | O32: Raw materials | P32: =G22+G23 -> 11.869404 | R32: Total | S32: Raw Materials | T32: =SUMIF($O$32:$O$50,S32,$P$32:$P$50) -> 11.869404 | V32: Parts per build | Y32: =Universal!parts_job -> 135 | AE32: Printer | AF32: Raw materials | AG32: =G22+G23 -> 11.869404 | AI32: Total | AJ32: Raw Materials | AK32: =SUMIF($O$32:$O$50,S32,$P$32:$P$50) -> 11.869404 | AM32: Parts per build | AP32: =Universal!parts_job -> 135
B33: Printer operations inputs | F33: Ovens required (rounded) | G33: =ROUNDUP(Universal!total_builds_yr/G32,0) -> 1 | J33: PPU utilization (hrs) | K33: =IFERROR(ROUNDUP(MAX(G12/G11,G46/G45)*K32,0),"N.A. ") -> N.A. | L33: hrs | N33: Printer | O33: Consumables | P33: =G25 -> 2.6331773 | S33: Consumables | T33: =SUMIF($O$32:$O$50,S33,$P$32:$P$50) -> 2.9109551 | V33: Nesting density | Y33: =G17 -> 0.51568461 | AE33: Printer | AF33: Consumables | AG33: =G25 -> 2.6331773 | AJ33: Consumables | AK33: =SUMIF($O$32:$O$50,S33,$P$32:$P$50) -> 2.9109551 | AM33: Nesting density | AP33: =X17
B34: Hours / day | C34: 16 | F34: Drying oven utilization | G34: =Universal!total_builds_yr*G31/G30 -> 1666.0631 | H34: hrs | J34: Powder processing investment | K34: =Universal!powder_process_msrp*IF(Universal!ppu_auto_on,K32,K30) -> 9795 | N34: Printer | O34: Depreciation | P34: =G24 -> 0.65249684 | S34: Depreciation | T34: =SUMIF($O$32:$O$50,S34,$P$32:$P$50) -> 1.1399153 | V34: Parts per furnace run | Y34: =IF(Universal!furnace_sel="DM",K9,K9) -> 216 | AE34: Printer | AF34: Labor | AG34: =G26 -> 0.082304527 | AJ34: Labor | AK34: =T35 -> 0.70055587 | AM34: Parts per furnace run | AP34: =IF(Universal!furnace_sel="DM",AB9,AB9)
B35: Days / week | C35: 7 | F35: Drying oven investment | G35: =IF(C14="TurboFuse",(Universal!xlink_msrp+1200)*G33,Universal!xlink_msrp*G33) -> 23540 | J35: ="Annual depreciation (@ "&Universal!dm_depr&" yrs)" -> Annual depreciation (@ 7 yrs) | K35: =K34/Universal!dm_depr+Universal!floor_rate*IF(Universal!ppu_auto_on,K32,K30)*Universal!powder_floorspace -> 1501.6857 | N35: Printer | O35: Labor | P35: =G26 -> 0.082304527 | S35: Labor | T35: =SUMIF($O$32:$O$50,S35,$P$32:$P$50) -> 0.70055587 | V35: Builds per furnace run | Y35: =Y34/Universal!parts_job -> 1.6 | AE35: Printer | AF35: Utilities | AG35: =G27 -> 0.056131891 | AJ35: Utilities | AK35: =T36 -> 1.8439126 | AM35: Builds per furnace run | AP35: =AP34/Universal!parts_job -> 0
B36: Weeks / year | C36: 50 | F36: ="Annual depreciation (@ "&Universal!dm_depr&" yrs)" -> Annual depreciation (@ 7 yrs) | G36: =G35/Universal!dm_depr+Universal!floor_rate*G33*Universal!xlink_floorspace -> 3490.8571 | J36: Depreciation $ / part | K36: =K35*IF(Universal!ppu_auto_on,K33,K31)/(Universal!avail_hours_yr*IF(Universal!ppu_auto_on,K32,K30))/Universal!part_req -> 0.027924708 | N36: Printer | O36: Utilities | P36: =G27 -> 0.056131891 | S36: Utilities | T36: =SUMIF($O$32:$O$50,S36,$P$32:$P$50) -> 1.8439126 | V36: Parts per week | Y36: =Y37/Universal!weeks_yr -> 400 | AE36: Drying Oven | AF36: Labor | AG36: =G38 -> 0.041152263 | AJ36: 3Yr Items | AK36: =T37 -> 0 | AM36: Parts per week | AP36: =AP37/Universal!weeks_yr -> 400
B37: Available hours / year | C37: =C34*C35*Universal!weeks_yr -> 5600 | F37: Depreciation $ / part | G37: =G36*G34/(Universal!total_hours_yr*G33)/Universal!part_req -> 0.034618978 | J37: Labor $ / part | K37: =Universal!labor_rate*Universal!total_builds_yr*IF(Universal!ppu_auto_on,Universal!ppu_auto_trnaround,K26/K27*Universal!powder_trnaround)/Universal!part_req -> 0.04442418 | N37: Drying Oven | O37: Depreciation | P37: =G37 -> 0.034618978 | S37: 3Yr Items | T37: =SUMIF($O$32:$O$50,S37,$P$32:$P$50) -> 0 | V37: Parts per year | Y37: =Universal!part_req -> 20000 | AE37: Drying Oven | AF37: Utilities | AG37: =G39 -> 0.027215141 | AJ37: Total | AK37: =SUM(AK32:AK36) -> 17.324828 | AM37: Parts per year | AP37: =Universal!part_req -> 20000
B38: Uptime | C38: 0.8 | F38: Labor $ / part | G38: =Universal!labor_rate*Universal!xlink_trnaround/G30*Universal!total_builds_yr/Universal!part_req -> 0.041152263 | J38: Utilities / part | K38: =Universal!power_rate*Universal!powder_pwr*IF(Universal!ppu_auto_on,G12,Universal!total_builds_yr*K26/K27)/Universal!part_req -> 0.00064503909 | N38: Drying Oven | O38: Labor | P38: =G38 -> 0.041152263 | S38: Total | T38: =SUM(T32:T37) -> 18.464743 | V38: Operating part cost | Y38: =P11 -> 17.324828 | AE38: Depowder | AF38: Labor | AG38: =G50 -> 0.4526749 | AM38: Operating part cost | AP38: =AG13 -> 17.324828
B39: Uptime hours / year | C39: =Universal!avail_hours_yr*Universal!uptime -> 4480 | F39: Utilities $ / part | G39: =Universal!power_rate*Universal!xlink_pwr*G34/Universal!part_req -> 0.027215141 | N39: Drying Oven | O39: Utilities | P39: =G39 -> 0.027215141 | V39: Operating cost / cc | Y39: =P13 -> 0.85729126 | AE39: Depowder | AF39: Utilities | AG39: =G51 -> 0.00084650206 | AI39: Total | AJ39: Raw Materials | AK39: =T32 -> 11.869404 | AM39: Operating cost / cc | AP39: =AG15 -> 0.85729126
B40: Good parts / printer / year | C40: =ROUND(Universal!good_parts_job/Universal!print_time_trn*Universal!uptime_hours_yr,0) -> 47454 | N40: Depowder | O40: Depreciation | P40: =G49 -> 0.026553946 | R40: Total | S40: Raw Materials | T40: =P32 -> 11.869404 | V40: Fully burdened part cost | Y40: =P17 -> 18.464743 | AE40: Furnace | AF40: Consumables | AG40: =IF(C15="No",0,K20) -> 0.27777778 | AJ40: Printer | AK40: =SUM(P33,P35,P36) -> 2.7716138 | AM40: Printer utilization | AP40: =AK14 -> 0.33717095
B41: Minimum config max capability | C41: =IF((MAX((C40/C31)/G32,(C40/C31)/G44))>1,Universal!part_capacity/(MAX((C40/C31)/G32,(C40/C31)/G44)),Universal!part_capacity) -> 47454 | E41: x | F41: Depowder part cost calculation | N41: Depowder | O41: Labor | P41: =G50 -> 0.4526749 | S41: Printer | T41: =SUMIF($N$33:$N$50,S41,$P$33:$P$50) -> 3.4241106 | V41: Fully burdened cost / cc | Y41: =P19 -> 0.91369814 | AE41: Furnace | AF41: Labor | AG41: =IF(C15="No",0,K21) -> 0.08 | AJ41: Drying Oven | AK41: =SUM(P38,P39) -> 0.068367404 | AM41: Furnace utilization | AP41: =AK17 -> 0.26420857
...

Sheet Layer_defaults
B1: P-1/P-50 Default Layer Thickness | C1: X shrink | D1: Y shrink | E1: Z shrink
A2: 17-4PH | B2: 0.065 | C2: 1.16 | D2: 1.165 | E2: 1.18
A3: 316L | B3: 0.065 | C3: 1.157 | D3: 1.153 | E3: 1.174
A4: 420 | B4: 0.05 | C4: 1.177 | D4: 1.18 | E4: 1.192
A5: 440C | B5: 0.05 | C5: 1.177 | D5: 1.18 | E5: 1.192
A6: DM HH Stainless | B6: 0.065 | C6: 1.157 | D6: 1.153 | E6: 1.174
A7: IN625 | B7: 0.05 | C7: 1.17 | D7: 1.173 | E7: 1.196
A8: IN718 | B8: 0.05 | C8: 1.17 | D8: 1.173 | E8: 1.196
A9: D2 | B9: 0.065 | C9: 1.157 | D9: 1.159 | E9: 1.203
A10: H13 | B10: 0.05 | C10: 1.157 | D10: 1.159 | E10: 1.203
A11: 4140 | B11: 0.05 | C11: 1.157 | D11: 1.157 | E11: 1.19
A12: Cu | B12: 0.05 | C12: 1.172 | D12: 1.181 | E12: 1.186
A13: Silver | B13: 0.04 | C13: 1.1424 | D13: 1.1433 | E13: 1.15
A14: Gold | B14: 0.04 | C14: 1.1424 | D14: 1.1433 | E14: 1.15
A15: Al 6061 | B15: 0.1 | C15: 1.13 | D15: 1.13 | E15: 1.15
A16: Ti-64 | B16: 0.065 | C16: 1.13 | D16: 1.13 | E16: 1.15
A17: M2 | B17: 0.065 | C17: 1.157 | D17: 1.159 | E17: 1.203
A18: S7 | B18: 0.065 | C18: 1.157 | D18: 1.159 | E18: 1.203
A19: 304L | B19: 0.065 | C19: 1.157 | D19: 1.153 | E19: 1.174
A20: CrMnMoN | B20: 0.065 | C20: 1.157 | D20: 1.153 | E20: 1.174
A21: WC-12Co | B21: 0.065 | C21: 1.157 | D21: 1.153 | E21: 1.174
A22: SiC

Sheet Shop
A2: x | B2: =MID(CELL("filename",A1),SEARCH("[",CELL("filename",A1))+1,LEN(CELL("filename",A1))-SEARCH("[",CELL("filename",A1))-16) -> #VALUE! | F2: SHOP SYSTEM | K2: Privileged & DM Confidential | M2: x | N2: Shop System part cost outputs
N3: DM equipment MSRP | P3: =G19+G34+G46+K47 -> #N/A | R3: ="Printed parts / "&C14&" build" -> Printed parts / 12L build | T3: =parts_job -> 360
A4: x | B4: Part inputs (pre-scaling) | E4: x | F4: Printer usage calculation | I4: x | J4: DM furnace part cost calculation | N4: =IF(C16="Shop","DM",C16&" cu ft MIM")&" furnace MSRP" -> DM furnace MSRP | P4: =IF(C16="Shop",K13,K33) -> N.A. | R4: Part nesting density | T4: =G16 -> 0.69668439
B5: X-dim (incl. supports) | C5: 15 | D5: mm | F5: Powder volume / part | G5: =part_vol_scale*Shop!bed_density -> 3564.869 | H5: mm3 | J5: Furnace parts / run | K5: =ROUNDDOWN((dm_furnace_x+furnace_xy_spacing)/(furnace_part_scale_x+furnace_xy_spacing),0)*ROUNDDOWN((dm_furnace_y+furnace_xy_spacing)/(furnace_part_scale_y+furnace_xy_spacing),0)*MIN(5,ROUNDDOWN(dm_furnace_z/(furnace_part_scale_z+furnace_z_spacing),0)) -> #N/A | N5: Total equipment MSRP | P5: =SUM(P3:P4) -> #N/A
B6: Y-dim (incl. supports) | C6: 16 | D6: mm | F6: Powder mass / part | G6: =G5*Shop!density_selected*1000 -> 28.518952 | H6: g | J6: Furnace loading parts / hour | K6: =C52 -> 240 | N6: =C14&" printers required" -> 12L printers required | P6: =G10 -> 1 | R6: Printer builds / week | T6: =T8/weeks_yr -> 17.32853
B7: Z-dim (incl. supports) | C7: 16 | D7: mm | F7: Powder mass / build | G7: =(G6*parts_job)/1000+((build_vol*Shop!bed_density*Shop!density_selected*powder_ratio)-(G6*parts_job)/1000)*powder_loss_percentage -> 10.348119 | H7: kg | J7: Run time + turnaround | K7: =43+K5/K6*2 -> #N/A | L7: hrs | N7: Furnaces required | P7: =IF(furnace_sel="Shop",K11,K31) -> N.A. | R7: Printer builds / month | T7: =T6*4 -> 69.31412
B8: Part volume | C8: =+part_x*part_y*part_z -> 3840 | D8: mm3 | F8: Binder volume / part | G8: =part_vol_scale*binder_ratio -> #N/A | H8: mm3 | J8: Time per printer build | K8: =IFERROR((good_parts_job/K5*K7),"N.A.") -> N.A. | L8: hrs | R8: Printer builds / year | T8: =total_builds_yr -> 831.76944
B9: Support volume | D9: mm3 | F9: Binder volume / build | G9: =G8*parts_job/10^6+(build_layers/C84+2)*binder_purge_vol/1000 -> #N/A | H9: L | J9: Build capacity / year | K9: =IFERROR(ROUNDDOWN(avail_hours_yr/K8,0),"N.A.") -> N.A. | N9: Operating (i.e. "running") part costs
B10: Part + support volume | C10: =Shop!part_only_vol+Shop!support_vol -> 3840 | D10: mm3 | F10: Printers required (rounded) | G10: =ROUNDUP(part_req/part_capacity,0) -> 1 | J10: Runs / year | K10: =IFERROR(ROUNDUP(part_req/K5,0),"N.A.") -> N.A. | N10: Printed part cost | P10: =P32+P33+P35+P36 -> #N/A | R10: =IF($C$15="Yes","Sintered","Green")&" parts / week" -> Sintered parts / week | T10: =T12/weeks_yr -> 6238.2708
F11: Printer utilization | G11: =part_req/good_parts_job*print_time_trn -> 3840.0023 | H11: hrs | J11: DM furnaces required (rounded) | K11: =IFERROR(ROUNDUP(total_builds_yr/K9,0),"N.A.") -> N.A. | N11: =IF(C15="Yes","Sintered","Green")&" part cost" -> Sintered part cost | P11: =T38-T34-T37 -> #N/A | R11: =IF($C$15="Yes","Sintered","Green")&" parts / month" -> Sintered parts / month | T11: =T10*4 -> 24953.083
A12: x | B12: Build inputs & process capacity | F12: Builds / year | G12: =part_req/good_parts_job -> 831.76944 | J12: DM furnace utilization | K12: =IFERROR(K7*K10,"N.A.") -> N.A. | L12: hrs | N12: =N10&" / cc" -> Printed part cost / cc | P12: =P10/Shop!part_only_vol*10^3 -> #N/A | R12: =IF($C$15="Yes","Sintered","Green")&" parts / year" -> Sintered parts / year | T12: =part_req -> 299437
B13: Pricing model | C13: Base | F13: Builds / month | G13: =G12/12 -> 69.31412 | J13: DM furnace investment | K13: =IFERROR(K11*dm_furnace_msrp,"N.A.") -> N.A. | N13: =N11&" / cc" -> Sintered part cost / cc | P13: =P11/Shop!part_only_vol*10^3 -> #N/A
B14: Build box size | C14: 12L | F14: Printer utilization (% of available) | G14: =G11/(avail_hours_yr*G10) -> 1.0000006 | J14: ="Annual depreciation (@ "&Shop!dm_depr&" yrs)" -> Annual depreciation (@ 5 yrs) | K14: =IFERROR(K13/Shop!dm_depr+(1.6*1.4)*K11*Shop!floor_rate,"N.A.") -> N.A. | R14: ="Printer util (QTY: "&G10&")" -> Printer util (QTY: 1) | T14: =G14 -> 1.0000006
B15: Include sintering? | C15: Yes | F15: Printer utilization (% 24x7) | G15: =G11/(24*7*52*G10) -> 0.4395607 | J15: Consumables $ / part | K15: =IFERROR(dm_furnace_consumables_run/K5+dm_furnace_consumables_material*(G6/1000),"N.A.") -> N.A. | N15: Burdened (i.e. "depreciated") part costs | R15: ="Oven util (QTY: "&G32&")" -> #N/A | T15: =G33/(total_hours_yr*G32*Shop!uptime) -> #N/A
B16: Furnace selection | C16: Shop | D16: =IF(OR(furnace_sel="Shop",furnace_sel="Continuous"),,"ft3") | F16: Nesting density | G16: =part_vol_scale*parts_job/build_vol -> 0.69668439 | J16: Depreciation $ / part | K16: =IFERROR(K12/(total_hours_yr*K11)*K14/part_req,"N.A.") -> N.A. | N16: Printed part cost | P16: =SUM(P32:P36) -> #N/A | R16: ="Depowder util (QTY: "&G44&")" -> Depowder util (QTY: 2) | T16: =G45/(avail_hours_yr*G44*Shop!uptime) -> 0.70397153
B17: Debind | C17: Integrated | J17: Labor $ / part | K17: =IFERROR(labor_rate*(K7-43)/K5,"N.A.") -> N.A. | N17: =IF(C15="Yes","Sintered","Green")&" part cost" -> Sintered part cost | P17: =T46 -> #N/A | R17: ="Furnace util (QTY: "&IF(furnace_sel="Shop",K11,K31)&")" -> Furnace util (QTY: N.A.) | T17: =IF(C16="Shop",K12/(total_hours_yr*K11*Shop!uptime),K32/(total_hours_yr*K31*Shop!uptime)) -> #VALUE!
B18: Limit furnace to QTY 1 | C18: No | E18: x | F18: Printer part cost calculation | J18: Utilities / part | K18: =IFERROR((1.25*power_rate*43+0.011*2400)/K5,"N.A.") -> N.A. | N18: Printed part cost / cc | P18: =P16/Shop!part_only_vol*10^3 -> #N/A
B19: Nested parts / job | C19: =ROUNDDOWN((Shop!build_x-Shop!printer_xy_border*2+Shop!printer_xy_spacing)/(part_scale_x+Shop!printer_xy_spacing),0)*ROUNDDOWN((Shop!build_y-Shop!printer_xy_border*2+Shop!printer_xy_spacing)/(part_scale_y+Shop!printer_xy_spacing),0)*ROUNDDOWN((Shop!build_z-Shop!printer_z_base+Shop!printer_z_spacing)/(part_scale_z+Shop!printer_z_spacing),0) -> 360 | F19: Printer investment (incl. build box) | G19: =G10*(printer_msrp+(C73/50-1)*printer_module_msrp)+G10*Shop!vacuum_msrp+MAX(2*G10,G32*G29+ROUNDUP(G30/print_time_trn,0))*Shop!buildbox_msrp+800*G10*2*3+1500+8000 -> #N/A | N19: =IF(C15="Yes","Sintered","Green")&" part cost / cc" -> Sintered part cost / cc | P19: =P17/Shop!part_only_vol*10^3 -> #N/A | R19: Labor hrs / year | T19: =1*total_builds_yr+0.5*total_builds_yr/2+G45+IF(C16="Shop",K5/K6*K10*2,K25/K26*K30*2)+0.25*(K46/K42) -> #N/A
B20: Build height | C20: =Shop!printer_z_base+(part_scale_z)*ROUNDDOWN((Shop!build_z-Shop!printer_z_base+Shop!printer_z_spacing)/(part_scale_z+Shop!printer_z_spacing),0)+Shop!printer_z_spacing*(ROUNDDOWN((Shop!build_z-Shop!printer_z_base+Shop!printer_z_spacing)/(part_scale_z+Shop!printer_z_spacing),0)-1) -> 42.72 | D20: mm | F20: ="Annual depreciation (@ "&Shop!dm_depr&" yrs)" -> Annual depreciation (@ 5 yrs) | G20: =G19/Shop!dm_depr+(2*0.8+0.56*0.57)*G10*Shop!floor_rate -> #N/A | I20: x | J20: MIM furnace part cost calculation | N20: Notes & assumptions:
B21: Override nesting | C21: No | F21: Powder $ / part | G21: =(G7*powder_price)/good_parts_job -> 2.3570715 | J21: Furnace selection | K21: =C16 -> Shop | L21: =IF(OR(furnace_sel="Shop",furnace_sel="Continuous"),,"ft3") | N21: 1. Pricing is not final unless on an official DM quote and is subject to change. Does not include installation, training, shipping, or taxes.
B22: Override parts / job | C22: 12 | F22: Binder $ / part | G22: =G9*binder_price/good_parts_job -> #N/A | J22: Furnace X-dim | K22: =C109 -> N.A. | L22: mm | N22: ="2. DM Equipment MSRP includes printer build boxes ("&MAX(2*G10,G32*G29+ROUNDUP(G30/print_time_trn,0))&"x), powder kegs, and transfer cart." -> #N/A
B23: Override build height | C23: 147 | D23: mm | F23: Depreciation $ / part | G23: =G11/(avail_hours_yr*G10)*G20/part_req -> #N/A | J23: Furnace Y-dim | K23: =C110 -> N.A. | L23: mm | N23: 3. Consumables includes printer items (e.g. printheads, wiper cartridges, etc.) and, if applicable, Desktop Metal Furnace items (e.g. setter plates, shelving, oil, liners, etc.).
B24: Layer thickness | C24: 0.075 | D24: mm | F24: Consumables $ / part | G24: =((build_layers/printhead_life*printhead_msrp)+(build_layers/Shop!wiper_life*Shop!wiper_msrp)+(G9/Shop!sponge_life*Shop!sponge_msrp))/good_parts_job -> #N/A | J24: Furnace Z-dim | K24: =C111 -> N.A. | L24: mm | N24: 4. Includes utilities costs for gas (as required), electricity, and floorspace.
B25: Layers | C25: =ROUNDUP(build_height/C24,0) -> 570 | F25: Labor $ / part | G25: =print_trnaround*labor_rate/good_parts_job -> 0.027777778 | J25: Furnace parts / run | K25: =IF(furnace_sel="Continuous",part_req,ROUNDDOWN((Shop!mim_furnace_x+furnace_xy_spacing)/(furnace_part_scale_x+furnace_xy_spacing),0)*ROUNDDOWN((Shop!mim_furnace_y+furnace_xy_spacing)/(furnace_part_scale_y+furnace_xy_spacing),0)*MIN(furnace_shelves,ROUNDDOWN(Shop!mim_furnace_z/(furnace_part_scale_z+Shop!Furnace_rack_thickness+furnace_z_spacing),0))) -> #VALUE! | N25: ="5. "&C41&" powder at "&TEXT(powder_price,"$0.00")&"/kg and binder at "&TEXT(binder_price,"$0.00")&"/L. Volume pricing may be available." -> 5. 17-4PH SS powder at $82.00/kg and binder at $300.00/L. Volume pricing may be available.
B26: ="Print time + "&print_trnaround&"hrs turnaround" -> Print time + 0.5hrs turnaround | C26: =C25*Shop!layer_speed/(60*60)+print_trnaround -> 4.6166667 | D26: hrs | F26: Utilities $ / part | G26: =power_rate*5*(print_time_trn-print_trnaround)/good_parts_job -> 0.0068611111 | J26: Furnace loading parts / hour | K26: =C52 -> 240 | N26: ="6. Key process assumptions: (i) "&C24*1000&" micron printed layer height; (ii) $"&labor_rate&"/hr labor rate; (iii) Printer, depowdering, and powder handling equipment @ "&C31&" x "&C32&" x "&weeks_yr&" x "&Shop!uptime*100&"% uptime" -> 6. Key process assumptions: (i) 75 micron printed layer height; (ii) $20/hr labor rate; (iii) Printer, depowdering, and powder handling equipment @ 16 x 5 x 48 x 100% uptime
B27: Overall process yield | C27: 1 | J27: Run time + turnaround | K27: =Shop!furnace_time_cycle+K25/K26*2 -> #VALUE! | L27: hrs | O27: =" (iv) "&G41&" parts/hr depowdering rate; (v) "&total_yield*100&"% overall process yield; (vi) "&Shop!dm_depr&"yr DM equipment depreciation;" -> (iv) 60 parts/hr depowdering rate; (v) 100% overall process yield; (vi) 5yr DM equipment depreciation;
B28: Good parts / job | C28: =IF(override_nesting="Yes",IF(C22=0,C19,C22),C19)*C27 -> 360 | E28: x | F28: Drying oven part cost calculation | J28: Time per printer build | K28: =IFERROR(good_parts_job/K25*K27,"N.A.") -> N.A. | L28: hrs | O28: =" (vii) Drying oven "&IF(C15="Yes","& sintering ",)&"equipment @ 24 x 7 x "&weeks_yr&" x "&Shop!uptime*100&"% uptime; (viii) "&IF(C15="Yes",Shop!furnace_depr&"yr MIM furnace depreciation; (iv) ",)&total_yield*100&"% overall process yield" -> (vii) Drying oven & sintering equipment @ 24 x 7 x 48 x 100% uptime; (viii) 10yr MIM furnace depreciation; (iv) 100% overall process yield
F29: Printer builds / oven run | G29: =IF(OR(Shop!s_model="4L",Shop!s_model="8L"),2,1) -> 1 | J29: Build capacity / year | K29: =IF(furnace_sel="Continuous",(240000/2.2)/(good_parts_job*part_vol*Shop!density_selected),ROUNDDOWN(avail_hours_yr/K28,0)) -> #VALUE!
A30: x | B30: Printer operations inputs | F30: ="Dry time + "&Shop!xlink_trnaround&"hrs turnaround" -> #N/A | G30: =C92*build_height/Shop!build_z+Shop!xlink_trnaround -> #N/A | H30: hrs | J30: Runs / year | K30: =IFERROR(ROUNDUP(part_req/K25,0),"N.A.") -> N.A.
B31: Hours / day | C31: 16 | F31: Build capacity / year | G31: =ROUNDDOWN(G29*total_hours_yr/G30,0) -> #N/A | J31: MIM furnaces required (rounded) | K31: =IFERROR(ROUNDUP(total_builds_yr/K29,0),"N.A.") -> N.A. | N31: ="Shop System "&C14&" "&LOWER(N11)&" allocation" -> Shop System 12L sintered part cost allocation | V31: Cost model template output
B32: Days / week | C32: 5 | F32: Ovens required (rounded) | G32: =ROUNDUP(total_builds_yr/G31,0) -> #N/A | J32: MIM furnace utilization | K32: =IFERROR(K27*K30,"N.A.") -> N.A. | L32: hrs | N32: Printer | O32: Raw materials | P32: =G21+G22 -> #N/A | R32: Total | S32: Raw Materials | T32: =SUMIF($O$32:$O$50,S32,$P$32:$P$50) -> #N/A | V32: Parts per build | Y32: =parts_job -> 360
B33: Weeks / year | C33: 48 | F33: Drying oven utilization | G33: =total_builds_yr*G30/G29 -> #N/A | H33: hrs | J33: MIM furnace investment | K33: =IFERROR(OFFSET(C126,furnace_index-1,)*K31,"N.A.") -> N.A. | N33: Printer | O33: Consumables | P33: =G24 -> #N/A | S33: Consumables | T33: =SUMIF($O$32:$O$50,S33,$P$32:$P$50) -> #N/A | V33: Nesting density | Y33: =G16 -> 0.69668439
B34: Printer available hours / year | C34: =C31*C32*weeks_yr -> 3840 | F34: Drying oven investment | G34: =G32*curing_msrp -> #N/A | J34: ="Annual depreciation (@ "&Shop!furnace_depr&" yrs)" -> Annual depreciation (@ 10 yrs) | K34: =IFERROR(K33/Shop!furnace_depr+OFFSET(C136,furnace_index-1,)*K31*Shop!floor_rate,"N.A.") -> N.A. | N34: Printer | O34: Depreciation | P34: =G23 -> #N/A | S34: Depreciation | T34: =SUMIF($O$32:$O$50,S34,$P$32:$P$50) -> #N/A | V34: Parts per furnace run | Y34: =IF(furnace_sel="Shop",K5,K25) -> #N/A
B35: Printer & furnace uptime | C35: 1 | F35: ="Annual depreciation (@ "&Shop!dm_depr&" yrs)" -> Annual depreciation (@ 5 yrs) | G35: =G34/Shop!dm_depr+(1*0.8)*G32*Shop!floor_rate -> #N/A | J35: Depreciation / part | K35: =IFERROR(K32/(IF(furnace_sel="Continuous",total_hours_yr,avail_hours_yr)*K31)*K34/part_req,"N.A.") -> N.A. | N35: Printer | O35: Labor | P35: =G25 -> 0.027777778 | S35: Labor | T35: =SUMIF($O$32:$O$50,S35,$P$32:$P$50) -> #N/A | V35: Builds per furnace run | Y35: =Y34/parts_job -> #N/A
B36: Printer uptime hours / year | C36: =avail_hours_yr*Shop!uptime -> 3840 | F36: Depreciation $ / part | G36: =G33/(total_hours_yr*G32)*G35/part_req -> #N/A | J36: Consumables / part | K36: =IF(furnace_sel="Continuous",Shop!furnace_power_cons*total_hours_yr/part_req,0) -> 0 | N36: Printer | O36: Utilities | P36: =G26 -> 0.0068611111 | S36: Utilities | T36: =SUMIF($O$32:$O$50,S36,$P$32:$P$50) -> #N/A | V36: Parts per week | Y36: =Y37/weeks_yr -> 6238.2708
B37: Good parts / printer / year | C37: =ROUND(good_parts_job/print_time_trn*Shop!uptime_hours_yr,0) -> 299437 | F37: Labor $ / part | G37: =(Shop!xlink_trnaround/G29*labor_rate*total_builds_yr)/part_req -> #N/A | J37: Labor $ / part | K37: =IFERROR(labor_rate*(K25/K26*2)/K25,"N.A.") -> N.A. | N37: Drying Oven | O37: Depreciation | P37: =G36 -> #N/A | S37: 3Yr Items | T37: =SUMIF($O$32:$O$50,S37,$P$32:$P$50) -> #N/A | V37: Parts per year | Y37: =part_req -> 299437
B38: Parts required / year | C38: =part_capacity -> 299437 | F38: Utilities $ / part | G38: =power_rate*2.97*G33/part_req -> #N/A | J38: Utilities / part | K38: =IF(furnace_sel="Continuous",Shop!furnace_gas_cons*total_hours_yr,(Shop!argon_rate*Shop!furnace_gas_cons+power_rate*Shop!furnace_power_cons)*(K27-K25/K26*2)*K30)/part_req -> #VALUE! | N38: Drying Oven | O38: Labor | P38: =G37 -> #N/A | S38: Total | T38: =SUM(T32:T37) -> #N/A | V38: Operating part cost | Y38: =P11 -> #N/A
N39: Drying Oven | O39: Utilities | P39: =G38 -> #N/A | V39: Operating cost / cc | Y39: =P13 -> #N/A
A40: x | B40: Cost & other inputs | E40: x | F40: Depowder part cost calculation | I40: x | J40: Powder blender part cost calculation | N40: Depowder | O40: Depreciation | P40: =G48 -> #N/A | R40: Total | S40: Raw Materials | T40: =P32 -> #N/A | V40: Fully burdened part cost | Y40: =P17 -> #N/A
B41: Material selection | C41: 17-4PH SS | F41: Depowdered parts / hour | G41: =C51 -> 60 | J41: Powder blender capacity | K41: 45 | L41: kg | N41: Depowder | O41: Labor | P41: =G49 -> 0.36111111 | S41: Printer | T41: =SUMIF($N$33:$N$50,S41,$P$33:$P$50) -> #N/A | V41: Fully burdened cost / cc | Y41: =P19 -> #N/A
...

Sheet P-1
A2: x | B2: =Shop!B2 -> #VALUE! | F2: PRODUCTION SYSTEM | K2: Privileged & DM Confidential | M2: x | N2: Production System part cost outputs
N3: DM equipment MSRP | P3: =G19+G34+G46+K47 -> #N/A | R3: ="Printed parts / "&C14&" build" -> Printed parts / P-1 build | T3: ='P-1'!parts_job -> 27
A4: x | B4: Part inputs (pre-scaling) | E4: x | F4: Printer usage calculation | I4: x | J4: Debind furnace part cost calculation | N4: =IF(C16="Shop","DM",IF('P-1'!furnace_sel<>"Continuous",C16&" cu ft MIM","Continuous"))&" furnace MSRP" -> 4 cu ft MIM furnace MSRP | P4: =K33+K14 -> #N/A | R4: Part nesting density | T4: =G16 -> 0.23023834
B5: X-dim (incl. supports) | C5: 22.1 | D5: mm | F5: Powder volume / part | G5: ='P-1'!part_vol_scale*'P-1'!bed_density -> 2341.2681 | H5: mm3 | J5: Debind furnace selection | K5: =K21 -> 4 | L5: ft3 | N5: Total equipment MSRP | P5: =SUM(P3:P4) -> #N/A
B6: Y-dim (incl. supports) | C6: 16 | D6: mm | F6: Powder mass / part | G6: =G5*density_selected*1000 -> 20.977762 | H6: g | J6: Furnace parts / run | K6: =K25 -> 3718 | N6: =C14&" printers required" -> P-1 printers required | P6: =G10 -> 1 | R6: Printer builds / week | T6: =T8/'P-1'!weeks_yr -> 105.65895
B7: Z-dim (incl. supports) | C7: 16 | D7: mm | F7: Powder mass / build | G7: =(G6*'P-1'!parts_job)/1000+(('P-1'!build_vol*'P-1'!bed_density*density_selected*'P-1'!powder_ratio)-(G6*'P-1'!parts_job)/1000)*'P-1'!powder_loss_percentage -> 0.6373693 | H7: kg | J7: Furnace loading parts / hour | K7: =K26 -> 240 | N7: Furnaces required | P7: =IF('P-1'!furnace_sel="Shop",K11,K31) -> 1 | R7: Printer builds / month | T7: =T6*4 -> 422.6358
B8: Part volume | C8: 2447 | D8: mm3 | F8: Binder volume / part | G8: ='P-1'!part_vol_scale*(1-'P-1'!bed_density)*'P-1'!binder_void_ratio -> 1248.6763 | H8: mm3 | J8: Run time + turnaround | K8: =6+K6/K7*1 -> 21.491667 | L8: hrs | R8: Printer builds / year | T8: ='P-1'!total_builds_yr -> 5071.6296
B9: Support volume | D9: mm3 | F9: Binder volume / build | G9: =G8*'P-1'!parts_job/10^6+('P-1'!build_layers/C84)*'P-1'!binder_purge_vol/1000 -> 0.06891426 | H9: L | J9: Time per printer build | K9: =('P-1'!good_parts_job/K6*K8) -> 0.15607181 | L9: hrs | N9: Operating part costs
B10: Part + support volume | C10: =part_only_vol+support_vol -> 2447 | D10: mm3 | F10: Printers required (rounded) | G10: =ROUNDUP('P-1'!part_req/'P-1'!part_capacity,0) -> 1 | J10: Build capacity / year | K10: =ROUNDDOWN('P-1'!total_hours_yr/K9,0) -> 51668 | N10: Printed part cost | P10: =P32+P33+P35+P36 -> 1.6835833 | R10: =IF($C$15="Yes","Sintered","Green")&" parts / week" -> Sintered parts / week | T10: =T12/'P-1'!weeks_yr -> 2852.7917
F11: Printer utilization | G11: ='P-1'!part_req/'P-1'!good_parts_job*'P-1'!print_time_trn -> 3840.0125 | H11: hrs | J11: Runs / year | K11: =K30 -> 37 | N11: =IF(C15="Yes","Sintered","Green")&" part cost" -> Sintered part cost | P11: =T37-T34 -> #N/A | R11: =IF($C$15="Yes","Sintered","Green")&" parts / month" -> Sintered parts / month | T11: =T10*4 -> 11411.167
